Traceback (most recent call last):
  File "/home/vishnu/3rd year/SMAI/smai-m24-assignments-Vishnuvarun077/assignments/3/mlpc.py", line 459, in <module>
    df = pd.read_csv("../../data/external/WineQT.csv")
  File "/home/vishnu/3rd year/SMAI/smai-m24-assignments-Vishnuvarun077/.venv/lib/python3.10/site-packages/pandas/io/parsers/readers.py", line 1026, in read_csv
    return _read(filepath_or_buffer, kwds)
  File "/home/vishnu/3rd year/SMAI/smai-m24-assignments-Vishnuvarun077/.venv/lib/python3.10/site-packages/pandas/io/parsers/readers.py", line 620, in _read
    parser = TextFileReader(filepath_or_buffer, **kwds)
  File "/home/vishnu/3rd year/SMAI/smai-m24-assignments-Vishnuvarun077/.venv/lib/python3.10/site-packages/pandas/io/parsers/readers.py", line 1620, in __init__
    self._engine = self._make_engine(f, self.engine)
  File "/home/vishnu/3rd year/SMAI/smai-m24-assignments-Vishnuvarun077/.venv/lib/python3.10/site-packages/pandas/io/parsers/readers.py", line 1880, in _make_engine
    self.handles = get_handle(
  File "/home/vishnu/3rd year/SMAI/smai-m24-assignments-Vishnuvarun077/.venv/lib/python3.10/site-packages/pandas/io/common.py", line 873, in get_handle
    handle = open(
FileNotFoundError: [Errno 2] No such file or directory: '../../data/external/WineQT.csv'
